Workbook

Sheet Read Me
A1: Content Integrity Pipeline Audit — TNQTech Integrity Central
A2: Architectural audit for real-world robustness, scalability, and de-bloating
A5: SOURCE BASIS AND SCOPE
A6: This audit was requested against https://github.com/pavan-182/content_integrity_checks. That repository could not be reached: it returned no result on GitHub search and a direct fetch was refused as an unverified/unindexed URL (consistent with a private, renamed, or not-yet-public repo). No live source code was reviewed to produce this workbook.
A8: Every finding below is instead grounded in the detailed technical design documentation supplied in this conversation: the Business Problem brief, PRD v1, and the four implementation-level design docs for Template Detection, LLM Response Trace, Tortured Phrase Detection, and the Numerical / Design Contradiction / Unverifiable Clinical Trial checks. Those docs describe real algorithms, thresholds, regex behavior, libraries, and — in one section — an explicit list of doc/code mismatches, so this is a substantive architecture audit, not a guess. Where a row makes an inference beyond what the docs state outright, it is phrased as a recommendation to verify against the actual code, not as a confirmed defect.
A10: If/when the repository becomes reachable, re-run this audit against the real code — component-level line numbers, actual duplication, and any drift from the documented design will only be visible there. This workbook is the right skeleton to pour that verification into.
A12: HOW TO USE THIS WORKBOOK
A13: 1. Pipeline Inventory — one row per subsystem, with a live Health Index computed from the component audit below it.
A14: 2. Component Audit — one row per module/behavior, with a Keep / Enhance / Remove verdict and a concrete action item.
A15: 3. Overengineering Log — the sharpest, named issues: fragile heuristics, silent failures, dead code, hardcoded edges.
A16: 4. Refactoring Roadmap — phased execution plan, ordered by trust/correctness risk first, then scale.
A18: Dropdowns are enabled on Verdict / Viability / Severity / Pattern Type / Effort columns so this can stay a living tracker as work lands.

Sheet Pipeline Inventory
A1: Pipeline Inventory & Health Index — Health Index and issue counts are LIVE FORMULAS reading the 'Component Audit' and 'Overengineering Log' sheets. Re-triaging a component there updates this sheet automatically.
A2: ID | B2: Pipeline / Subsystem | C2: Data Flow (Input → Output) | D2: Entry Point | E2: Exit Point | F2: Primary Tech Stack | G2: # Components Audited | H2: # Keep | I2: # Enhance | J2: # Remove | K2: Health Index % | L2: High/Critical Issues Open | M2: Current Architectural Bottleneck
A3: P1 | B3: XML Ingestion & Record Parsing | C3: Raw submission XML → ParsedRecord objects (id, title, abstract, sections, authors, affiliations, trial IDs) | D3: Batch of ~6,000 ASCO XML abstracts | E3: ParsedRecord list consumed by every detector | F3: lxml; Python re | G3: =COUNTIF('Component Audit'!$A:$A,$B3) | H3: =COUNTIFS('Component Audit'!$A:$A,$B3,'Component Audit'!$E:$E,"Keep") | I3: =COUNTIFS('Component Audit'!$A:$A,$B3,'Component Audit'!$E:$E,"Enhance") | J3: =COUNTIFS('Component Audit'!$A:$A,$B3,'Component Audit'!$E:$E,"Remove") | K3: =IFERROR(ROUND((H3*1+I3*0.5)/G3*100,0),"N/A") | L3: =COUNTIFS('Overengineering Log'!$B:$B,"*"&$B3&"*",'Overengineering Log'!$F:$F,"Critical")+COUNTIFS('Overengineering Log'!$B:$B,"*"&$B3&"*",'Overengineering Log'!$F:$F,"High") | M3: Undocumented/duplicated pre-processing (dedup, sentence-splitting) creates invisible correctness risk shared by every downstream detector.
A4: P2 | B4: Orchestration & Risk Aggregation | C4: ParsedRecord list → per-check Finding[] → aggregated overall_risk + report payload | D4: Parsed record set | E4: Consolidated content-integrity report + overall_risk field | F4: Python orchestration layer; per-detector config; React (frontend risk calc) | G4: =COUNTIF('Component Audit'!$A:$A,$B4) | H4: =COUNTIFS('Component Audit'!$A:$A,$B4,'Component Audit'!$E:$E,"Keep") | I4: =COUNTIFS('Component Audit'!$A:$A,$B4,'Component Audit'!$E:$E,"Enhance") | J4: =COUNTIFS('Component Audit'!$A:$A,$B4,'Component Audit'!$E:$E,"Remove") | K4: =IFERROR(ROUND((H4*1+I4*0.5)/G4*100,0),"N/A") | L4: =COUNTIFS('Overengineering Log'!$B:$B,"*"&$B4&"*",'Overengineering Log'!$F:$F,"Critical")+COUNTIFS('Overengineering Log'!$B:$B,"*"&$B4&"*",'Overengineering Log'!$F:$F,"High") | M4: Binary High/Low collapse discards the graded priority every detector already computes; thresholds scattered with no central config.
A5: P3 | B5: Template Detection (Cross-Author) | C5: ParsedRecord[] → original/normalized/masked text → candidate pairs → pair classification → Templating flag + Template Evidence rows | D5: Title, abstract, sections per record | E5: Templating (Cross-Author) flag + Template Evidence sheet rows | F5: Python regex; difflib.SequenceMatcher; BLAKE2b/SHA-256 fingerprints; optional HF Transformers (PubMedBERT) / SciSpaCy | G5: =COUNTIF('Component Audit'!$A:$A,$B5) | H5: =COUNTIFS('Component Audit'!$A:$A,$B5,'Component Audit'!$E:$E,"Keep") | I5: =COUNTIFS('Component Audit'!$A:$A,$B5,'Component Audit'!$E:$E,"Enhance") | J5: =COUNTIFS('Component Audit'!$A:$A,$B5,'Component Audit'!$E:$E,"Remove") | K5: =IFERROR(ROUND((H5*1+I5*0.5)/G5*100,0),"N/A") | L5: =COUNTIFS('Overengineering Log'!$B:$B,"*"&$B5&"*",'Overengineering Log'!$F:$F,"Critical")+COUNTIFS('Overengineering Log'!$B:$B,"*"&$B5&"*",'Overengineering Log'!$F:$F,"High") | M5: Pairwise candidate comparison scales only to a single annual batch; a fully-built family-clustering capability sits unused.
A6: P4 | B6: LLM Response Trace | C6: Formatting-preserved title/abstract → regex + GPT-OSS candidates → verified & validated findings | D6: Title/abstract with preserved formatting | E6: LLM Response Trace findings (confirmed/rejected/uncertain) | F6: lxml; Python re (YAML rule catalogue); GPT-OSS 20B via TNQ IntelliHub | G6: =COUNTIF('Component Audit'!$A:$A,$B6) | H6: =COUNTIFS('Component Audit'!$A:$A,$B6,'Component Audit'!$E:$E,"Keep") | I6: =COUNTIFS('Component Audit'!$A:$A,$B6,'Component Audit'!$E:$E,"Enhance") | J6: =COUNTIFS('Component Audit'!$A:$A,$B6,'Component Audit'!$E:$E,"Remove") | K6: =IFERROR(ROUND((H6*1+I6*0.5)/G6*100,0),"N/A") | L6: =COUNTIFS('Overengineering Log'!$B:$B,"*"&$B6&"*",'Overengineering Log'!$F:$F,"Critical")+COUNTIFS('Overengineering Log'!$B:$B,"*"&$B6&"*",'Overengineering Log'!$F:$F,"High") | M6: Best-architected pipeline in this audit; residual fragility only in quote/code-block context detection.
A7: P5 | B7: Tortured Phrase Detection | C7: Title/abstract → dictionary+regex candidates (known) & sentence-level GPT-OSS candidates (new) → validated findings | D7: Title, abstract text | E7: Confirmed tortured-phrase findings; new-phrase discovery candidates | F7: Python re; CSV rule dictionary; GPT-OSS 20B (temperature=0) | G7: =COUNTIF('Component Audit'!$A:$A,$B7) | H7: =COUNTIFS('Component Audit'!$A:$A,$B7,'Component Audit'!$E:$E,"Keep") | I7: =COUNTIFS('Component Audit'!$A:$A,$B7,'Component Audit'!$E:$E,"Enhance") | J7: =COUNTIFS('Component Audit'!$A:$A,$B7,'Component Audit'!$E:$E,"Remove") | K7: =IFERROR(ROUND((H7*1+I7*0.5)/G7*100,0),"N/A") | L7: =COUNTIFS('Overengineering Log'!$B:$B,"*"&$B7&"*",'Overengineering Log'!$F:$F,"Critical")+COUNTIFS('Overengineering Log'!$B:$B,"*"&$B7&"*",'Overengineering Log'!$F:$F,"High") | M7: Correctness bug: the proximity operator (~N) in dictionary syntax is parsed but never enforced.
A8: P6 | B8: Numerical Contradiction | C8: Abstract sentences → regex numeric claims → arithmetic/boundary rules → findings | D8: Abstract text (section-aware where structured) | E8: Numerical contradiction findings (no LLM stage) | F8: Python re (fully deterministic, no ML/LLM) | G8: =COUNTIF('Component Audit'!$A:$A,$B8) | H8: =COUNTIFS('Component Audit'!$A:$A,$B8,'Component Audit'!$E:$E,"Keep") | I8: =COUNTIFS('Component Audit'!$A:$A,$B8,'Component Audit'!$E:$E,"Enhance") | J8: =COUNTIFS('Component Audit'!$A:$A,$B8,'Component Audit'!$E:$E,"Remove") | K8: =IFERROR(ROUND((H8*1+I8*0.5)/G8*100,0),"N/A") | L8: =COUNTIFS('Overengineering Log'!$B:$B,"*"&$B8&"*",'Overengineering Log'!$F:$F,"Critical")+COUNTIFS('Overengineering Log'!$B:$B,"*"&$B8&"*",'Overengineering Log'!$F:$F,"High") | M8: Sentence-local-only reasoning misses the most common cross-sentence N-vs-percentage pattern in real abstracts.
A9: P7 | B9: Design Contradiction | C9: Title + abstract sections → regex design-attribute claims → fixed incompatibility rules → component/context suppression → optional LLM annotation | D9: Title, abstract sections | E9: Design contradiction findings (+ optional non-gating LLM annotation) | F9: Python re; itertools; optional GPT-OSS 20B via IntelliHub | G9: =COUNTIF('Component Audit'!$A:$A,$B9) | H9: =COUNTIFS('Component Audit'!$A:$A,$B9,'Component Audit'!$E:$E,"Keep") | I9: =COUNTIFS('Component Audit'!$A:$A,$B9,'Component Audit'!$E:$E,"Enhance") | J9: =COUNTIFS('Component Audit'!$A:$A,$B9,'Component Audit'!$E:$E,"Remove") | K9: =IFERROR(ROUND((H9*1+I9*0.5)/G9*100,0),"N/A") | L9: =COUNTIFS('Overengineering Log'!$B:$B,"*"&$B9&"*",'Overengineering Log'!$F:$F,"Critical")+COUNTIFS('Overengineering Log'!$B:$B,"*"&$B9&"*",'Overengineering Log'!$F:$F,"High") | M9: LLM validation result is computed but never gates the surfaced flag — inconsistent with the other two LLM-validated checks.
A10: P8 | B10: Unverifiable Clinical Trial | C10: Title + abstract → registry ID / registration-phrase regex → format validation → (valid IDs only) ClinicalTrials.gov API v2 lookup | D10: Title, abstract text | E10: Trial verification findings (not_found / invalid / placeholder / unsupported registry) | F10: Python re; urllib.request; ClinicalTrials.gov API v2; JSON file cache | G10: =COUNTIF('Component Audit'!$A:$A,$B10) | H10: =COUNTIFS('Component Audit'!$A:$A,$B10,'Component Audit'!$E:$E,"Keep") | I10: =COUNTIFS('Component Audit'!$A:$A,$B10,'Component Audit'!$E:$E,"Enhance") | J10: =COUNTIFS('Component Audit'!$A:$A,$B10,'Component Audit'!$E:$E,"Remove") | K10: =IFERROR(ROUND((H10*1+I10*0.5)/G10*100,0),"N/A") | L10: =COUNTIFS('Overengineering Log'!$B:$B,"*"&$B10&"*",'Overengineering Log'!$F:$F,"Critical")+COUNTIFS('Overengineering Log'!$B:$B,"*"&$B10&"*",'Overengineering Log'!$F:$F,"High") | M10: Best-engineered external dependency in the system (timeout/retry/backoff/cache); registry coverage list is the real gap.
A11: P9 | B11: Consolidated Workbook / Reporting | C11: Finding[] across all six checks → All Abstracts / Check Detail / Template Evidence sheets in one XLSX | D11: Findings from P3–P8 | E11: Editor-facing consolidated .xlsx workbook | F11: XLSX export layer per PRD (openpyxl/pandas-style) | G11: =COUNTIF('Component Audit'!$A:$A,$B11) | H11: =COUNTIFS('Component Audit'!$A:$A,$B11,'Component Audit'!$E:$E,"Keep") | I11: =COUNTIFS('Component Audit'!$A:$A,$B11,'Component Audit'!$E:$E,"Enhance") | J11: =COUNTIFS('Component Audit'!$A:$A,$B11,'Component Audit'!$E:$E,"Remove") | K11: =IFERROR(ROUND((H11*1+I11*0.5)/G11*100,0),"N/A") | L11: =COUNTIFS('Overengineering Log'!$B:$B,"*"&$B11&"*",'Overengineering Log'!$F:$F,"Critical")+COUNTIFS('Overengineering Log'!$B:$B,"*"&$B11&"*",'Overengineering Log'!$F:$F,"High") | M11: Multiple structured fields computed internally (numeric deltas, trial metadata, validation reasons) are silently dropped before export.
A12: P10 | B12: Editor Frontend & Evals | C12: Consolidated JSON payload → per-submission review screens + Evals validation view | D12: Consolidated report JSON | E12: Rendered editor review UI | F12: React frontend; JSON checks object | G12: =COUNTIF('Component Audit'!$A:$A,$B12) | H12: =COUNTIFS('Component Audit'!$A:$A,$B12,'Component Audit'!$E:$E,"Keep") | I12: =COUNTIFS('Component Audit'!$A:$A,$B12,'Component Audit'!$E:$E,"Enhance") | J12: =COUNTIFS('Component Audit'!$A:$A,$B12,'Component Audit'!$E:$E,"Remove") | K12: =IFERROR(ROUND((H12*1+I12*0.5)/G12*100,0),"N/A") | L12: =COUNTIFS('Overengineering Log'!$B:$B,"*"&$B12&"*",'Overengineering Log'!$F:$F,"Critical")+COUNTIFS('Overengineering Log'!$B:$B,"*"&$B12&"*",'Overengineering Log'!$F:$F,"High") | M12: Mirrors the P2 binary-risk problem on the UI side; Evals view covers only 2 of the 3 LLM-validated checks.

Sheet Component Audit
A1: Component-Level Audit & Triage — every row is grounded in a specific, named behavior from the technical design docs. Verdict/Priority are dropdown-editable so this can be re-triaged as work lands or as the live repo becomes reviewable.
A2: Pipeline Name | B2: Component / Module | C2: Current Implementation | D2: Real-World Viability | E2: Verdict | F2: Action Items | G2: Source Reference | H2: Priority | I2: Resolution Status (Phase 0/1 verification)
A3: XML Ingestion & Record Parsing | B3: XML Parser (lxml) | C3: lxml parses raw submission XML into ParsedRecord objects; extracts ID, title, abstract, structured sections, authors, affiliations, trial IDs. | D3: Medium | E3: Enhance | F3: Add a schema-tolerant fallback (recover=True or a secondary parser) plus structured parse-failure logging with reason codes, instead of the current 'remove records whose parsing failed' silent drop. | G3: Template Detection §2; Numerical/Design/Trial §1 | H3: P2
A4: XML Ingestion & Record Parsing | B4: Duplicate Record ID Resolution | C4: 'Duplicate record IDs are also resolved before comparison' -- no algorithm, matching key, or collision policy is documented. | D4: Low | E4: Enhance | F4: Make this a named, unit-tested function; log collision counts; document the tie-break rule (first-seen wins? most-complete record wins?). | G4: Template Detection §2 | H4: P1
A5: XML Ingestion & Record Parsing | B5: Sentence Splitter (regex `(?<=[.!?])\s+`) | C5: Naive punctuation-lookbehind regex, independently reimplemented in Numerical, Design, and Clinical Trial detectors (and implied elsewhere). | D5: Medium | E5: Enhance | F5: Extract one shared, abbreviation-aware sentence tokenizer (e.g. pySBD or a spaCy rule-based sentencizer) and delete the per-pipeline copies. | G5: Numerical/Design/Trial §1 (shared pipeline behaviour) | H5: P1 | I5: Partially resolved — Phase 1 (2026-08-19). Investigation found 8 independent implementations, not the 3 named here. Consolidated the true duplicates (identical naive-regex intent) into one content_integrity.utils.split_sentences(): template_matching_common._sentence_split (already shared by 5 detectors) now delegates to it; entity_substitutions.py, signal_validation.py, and enriched_reporting.py repointed, deleting their local copies. Also fixed a latent bug this duplication caused: entity_extraction._sentence_index derived its count from a different regex than entity_substitutions used to build its sentence list, so lookups could land in the wrong sentence — both now derive from the same split_sentences() call. NOT done: this is still the naive regex, not an abbreviation-aware tokenizer (Fig./vs./e.g. still fracture sentences); template_features._sentence_spans, llm_trace_context._sentence_spans, and tortured_phrase._SENTENCE_BREAK_RE were deliberately left untouched (span/boundary contract, not a drop-in duplicate) for the Phase 3 abbreviation-aware pass.
A6: XML Ingestion & Record Parsing | B6: Structured Section Extraction (Background/Methods/Results/Conclusions) | C6: Deterministic tag-based retention of structured abstract sections, kept separate so downstream checks can compare Results↔Results, Methods↔Methods. | D6: High | E6: Keep | F6: No major change. Add a fallback heuristic (e.g. bolded run-in headings) for abstracts with non-standard or free-text section labels. | G6: Template Detection §2 | H6: P3
A7: XML Ingestion & Record Parsing | B7: Failed/Empty Record Filtering | C7: Records with failed parsing or no usable title/abstract text are removed before detectors run. | D7: High | E7: Keep | F7: Emit exclusion counts + reasons into run metadata instead of a silent drop -- the PRD explicitly requires the workbook to 'show all abstracts and run metadata' even when nothing is found. | G7: Numerical/Design/Trial §1; PRD v1 §12 edge cases | H7: P1 | I7: Resolved — Phase 0 (2026-08-19). pipeline.py now emits one OperationalIssue per record excluded from numerical/design/trial checks (component=numerical_contradiction / design_contradiction / unverifiable_clinical_trial, error_type=record_excluded_parse_failed or record_excluded_no_text) instead of a silent drop, plus comparable_record_count and records_excluded_from_numerical_design_trial_checks in run metadata. Verified: a record that previously read as a clean pass on these 3 checks now shows operational_failure=True.
A8: Orchestration & Risk Aggregation | B8: Overall Risk Aggregation Rule | C8: Frontend rule: any one content check flagged -> overall_risk = High; no checks flagged -> Low. No active Moderate path. | D8: Low | E8: Enhance | F8: Replace the binary collapse with the graded High/Medium/Low/None model the PRD itself specifies and that every detector already computes per-check. | G8: Numerical/Design/Trial §28 | H8: P0
A9: Orchestration & Risk Aggregation | B9: Cross-Pipeline Threshold / Config Management | C9: At least 15 numeric thresholds (similarity cutoffs, word-count minimums, confidence mappings, timeouts, tolerances) are hardcoded independently inside each detector module. | D9: High | E9: Keep | F9: Centralize into one versioned config, extending the dictionary/pattern-version discipline already used for tortured phrases to every threshold. | G9: Cross-pipeline (Template §4, Tortured Phrase §13, Numerical §5, Trial §21) | H9: P2 | I9: Resolved — Phase 1 (2026-08-19). All threshold/magic-number constants (~50, across 15 files) relocated to content_integrity/thresholds.py; a repo-wide grep for scattered module-level numeric constants now returns zero hits outside that file. Versioned via the git commit sha already stamped in run metadata (Phase 0) rather than a separate content-hash scheme — a deliberate, approved alternative to literally extending the tortured-phrase dictionary's sha256-versioning pattern, since these are code-tuned knobs, not an externally-edited catalogue.
A10: Orchestration & Risk Aggregation | B10: LLM Call Orchestration (GPT-OSS usage across 3 pipelines) | C10: Tortured Phrase, LLM Response Trace, and Design Contradiction each call GPT-OSS independently; only the ClinicalTrials.gov adapter documents timeout/retry/backoff. | D10: High | E10: Keep | F10: Build one shared LLM client wrapper (timeout, retry/backoff, batching, cost/latency telemetry) reused by all three call sites, mirroring the registry adapter's resilience pattern. | G10: LLM Response Trace §3-8; Tortured Phrase §13, §19; Design Contradiction §15; Trial §22 | H10: P1 | I10: Resolved — Phase 0 (2026-08-19). One shared IntelliHubGPTOSSClient (validators/context_validator.py) already served every GPT-OSS call site (5, not just 3: tortured-phrase validation, LLM-trace validation, design-contradiction validation, nonsense-candidate, semantic-trace discovery) with timeout/retry/backoff; added the missing piece — a CallStats dataclass instrumented once in _request(), giving request/success/failure/retry counts and total/avg/max latency, surfaced as llm_gateway_* fields in run metadata. Batching already existed per call site.
A11: Orchestration & Risk Aggregation | B11: Run Metadata & Dictionary Versioning | C11: PRD risk mitigation calls for storing dictionary version and screening-run metadata; only documented in detail for the tortured-phrase CSV. | D11: High | E11: Keep | F11: Confirm and extend version stamping to the LLM-trace YAML catalogue and the design-contradiction rule table so every rule source is auditable the same way. | G11: PRD v1 §13 Risks/Mitigations | H11: P2 | I11: Resolved — Phase 0 (2026-08-19), completed today. LLM-trace YAML catalogue version/checksum already stamped pre-existing; added template_feature_version, template_pair_classifier_version, template_signal_validation_version, template_family_version, editorial_scoring_version, entity_vocabulary_version, and — closing the one remaining gap this row named — design_contradiction_rule_table_version and design_contradiction_prompt_version (previously unstamped). Every rule source in the system is now version-stamped in run metadata.
A12: Template Detection (Cross-Author) | B12: Entity Masking (deterministic regex/biomedical rules) | C12: Regex + biomedical vocabulary rules replace genes, drugs, diseases, trial IDs, percentages, etc. with placeholder tokens before structural comparison. | D12: Medium | E12: Enhance | F12: Appropriately precision-first for V1; the risk is vocabulary drift. Add a scheduled refresh against an external source (e.g. HGNC gene symbols, WHO INN drug stems) instead of a static in-repo list. | G12: Template Detection §4 | H12: P2
A13: Template Detection (Cross-Author) | B13: Optional PubMedBERT / SciSpaCy NER enrichment | C13: Model-based biomedical NER can supplement the regex masking layer; default confidence threshold 0.80. Explicitly optional. | D13: Medium | E13: Keep | F13: Genuinely additive and non-blocking. Document graceful degradation to regex-only when the model is unavailable or times out -- current behaviour on model failure is unspecified. | G13: Template Detection §4 | H13: P2
A14: Template Detection (Cross-Author) | B14: Candidate Retrieval (prefix/length blocking + entity-shape blocking + BLAKE2b fingerprints + 5-word n-gram sharing + masked-title retrieval) | C14: Five independent heuristic blocking strategies combine to decide which abstract pairs get the expensive deep comparison. | D14: Medium | E14: Enhance | F14: Fine at ~6,000 abstracts/year; does not scale to multi-year cumulative comparison (a PRD open question). Add an ANN/MinHash-LSH candidate layer ahead of the existing deterministic classifiers -- classification logic itself stays unchanged. | G14: Template Detection §5 | H14: P1
A15: Template Detection (Cross-Author) | B15: Direct-Text-Reuse Detector (SequenceMatcher + generic-phrase filtering + corpus-aware distinctive sentences) | C15: difflib.SequenceMatcher on word tokens, with generic-boilerplate filtering and a corpus-frequency check so rare shared sentences count more than common ones. | D15: High | E15: Keep | F15: No behavioural change needed. difflib.SequenceMatcher is O(n·m); benchmark against rapidfuzz as a drop-in if runtime becomes an issue at scale. | G15: Template Detection §6 | H15: P3
A16: Template Detection (Cross-Author) | B16: Entity-Normalized Template Detector (masked ≥0.88 AND original ≥0.55) | C16: Dual-similarity guard requiring both masked-structure similarity and a minimum of real original-wording overlap before a structural match counts. | D16: High | E16: Keep | F16: Well-reasoned anti-false-positive design (prevents two unrelated abstracts becoming a finding purely from placeholder collapse). Document the rationale inline in code, not only in the design doc. | G16: Template Detection §7 | H16: P3
A17: Template Detection (Cross-Author) | B17: Evidence Combination (primary = strongest signal, not summed; supporting adds ≤0.25) | C17: Multiple primary signals are not additive -- the strongest one is used; supporting evidence can only nudge the score, never create a finding alone. | D17: High | E17: Keep | F17: No change. This correctly prevents several mediocre signals from outscoring one real duplicate. | G17: Template Detection §8 | H17: P3
A18: Template Detection (Cross-Author) | B18: Same-Study / Companion-Study Context Layer | C18: Deterministic keyword/overlap checks (trial IDs, authors, 'subgroup analysis', 'interim analysis', etc.) explain away legitimate reuse; never increases suspicion. | D18: Medium | E18: Enhance | F18: Will miss paraphrased equivalents ('a further look at the same cohort'). Because a miss here only causes an unnecessary editor review (not a missed integrity signal), this is a lower-severity, good candidate for a lightweight LLM/embedding check. | G18: Template Detection §9 | H18: P2
A19: Template Detection (Cross-Author) | B19: Template-Family Graph Clustering | C19: Template pairs are modeled as graph edges; connected components of ≥3 abstracts can be identified as families -- fully built, explicitly 'not surfaced to editors.' | D19: Low | E19: Keep | F19: Prune-or-ship decision: either add a minimal Template Family view (a 5-abstract family is a much stronger signal than 5 separate pair rows) or delete the code path to stop paying its maintenance cost. | G19: Template Detection §12 | H19: P1 | I19: Deferred, not shipped or removed — Phase 1 (2026-08-19), by explicit product decision. The data already reaches content_integrity_results.json's template_families array; it still does not reach the Editor Triage Workbook or frontend. Decision: keep the code, do not build a workbook/UI view yet (value to editors unproven), do not delete it either. Documented in family_clustering.py's module docstring so this reads as a deliberate open decision, not abandoned work. Verdict changed from 'Remove' to 'Keep' to reflect that the code is being retained, not pruned; this is not the audit's proposed prune-or-ship resolution.
A20: LLM Response Trace | B20: Format-Preserving Text Extraction | C20: Keeps line breaks, headings, Markdown fences, quotes, and User:/Assistant: labels intact, because formatting itself is evidence of copied chat content. | D20: High | E20: Keep | F20: No change needed. | G20: LLM Response Trace §2 | H20: P3
A21: LLM Response Trace | B21: Known-Pattern Regex Catalogue (YAML rules) | C21: Known LLM-residue phrases live in a YAML rule file matched with Python re, separable from code changes. | D21: Medium | E21: Keep | F21: Good practice -- externalized, versionable rules. Recommend the Design Contradiction detector adopt the same YAML pattern (it currently hardcodes its rule table in Python). | G21: LLM Response Trace §3 | H21: P2
A22: LLM Response Trace | B22: GPT-OSS Semantic Variant / Novel-Pattern Detection | C22: GPT-OSS 20B maps unseen wording back to known rule categories or flags a genuinely novel candidate; explicitly does not judge AI authorship by style/polish. | D22: High | E22: Keep | F22: No major change. This is the clearest example in the system of an LLM used for exactly what it's good at (semantic generalization) without overreaching into a judgment it's told not to make. | G22: LLM Response Trace §4 | H22: P3
A23: LLM Response Trace | B23: Evidence Verification (LLM phrase must literal-match source exactly once) | C23: Any phrase GPT-OSS reports is re-searched in the original preserved text; 0 or >1 matches reject the finding, exactly 1 match restores the exact source characters. | D23: High | E23: Keep | F23: Excellent anti-hallucination guardrail. Use this exact pattern as the template for the equivalent check already present in Tortured Phrase discovery (§20) -- keep both aligned as the catalogue evolves. | G23: LLM Response Trace §5 | H23: P3
A24: LLM Response Trace | B24: Regex/Semantic Merge & Dedup by Source Position | C24: Overlapping regex and LLM findings are deduplicated; deterministic regex match is preferred over semantic variant, which is preferred over novel candidate. | D24: High | E24: Keep | F24: No change needed. | G24: LLM Response Trace §6 | H24: P3
A25: LLM Response Trace | B25: Context Extraction (quote / blockquote / code-block detection) | C25: Deterministic Python regex/string rules extract the surrounding sentence and detect whether a match sits inside quoted or fenced text. | D25: Medium | E25: Enhance | F25: Brittle against smart/curly quotes, nested quotes, or quotes spanning multiple sentences. Normalize Unicode quote characters before detection. | G25: LLM Response Trace §7 | H25: P2
A26: LLM Response Trace | B26: GPT-OSS Contextual Validation (confirmed/rejected/uncertain) | C26: Runs for every context-sensitive finding; a small set of very explicit rules are marked 'not_required' and skip a second model call. | D26: High | E26: Keep | F26: No change needed -- correctly gates the surfaced result, unlike the equivalent step in Design Contradiction (see that pipeline's audit). | G26: LLM Response Trace §8 | H26: P3
A27: LLM Response Trace | B27: Rule-Based Review Priority (no probability score, no ML weighting) | C27: Priority (High/Medium/Low/none) comes from an explicit lookup table of evidence type, not a trained or weighted model. | D27: High | E27: Keep | F27: Appropriately explainable for an editorial-trust context; no change needed. | G27: LLM Response Trace §9 | H27: P3
A28: Tortured Phrase Detection | B28: Dictionary Loader + Token/Bigram Candidate Index | C28: Tortured-phrase CSV is indexed by first one-to-two tokens for fast candidate lookup before the real regex match runs. | D28: High | E28: Keep | F28: No change needed -- correctly scoped as a retrieval filter only, not the match itself. | G28: Tortured Phrase §5.1 | H28: P3
A29: Tortured Phrase Detection | B29: Regex Phrase Matcher (incl. wildcard prefix, punctuation tolerance, word-boundary guards) | C29: Full regex match after candidate retrieval; tolerates punctuation/whitespace variants, blocks cross-sentence matches, supports `mechan*`-style prefix wildcards. | D29: Medium | E29: Enhance | F29: Solid overall, but the dictionary's `~5` proximity operator is parsed and then silently discarded rather than enforced or rejected -- fix or fail loudly at rule-load time. | G29: Tortured Phrase §6-8, §10 | H29: P0
A30: Tortured Phrase Detection | B30: AND / OR / NOT Context Conditions | C30: Regex-based presence/absence checks let a dictionary rule require or exclude nearby context words. | D30: High | E30: Keep | F30: No change needed. | G30: Tortured Phrase §9 | H30: P3
A31: Tortured Phrase Detection | B31: Mandatory GPT-OSS Validation (temperature=0) for Known-Phrase Candidates | C31: Every deterministic tortured-phrase match is validated by GPT-OSS with matched phrase, expected term, and surrounding context before it becomes a finding. | D31: High | E31: Keep | F31: No change needed. Correctly gates the result, matching LLM Response Trace's pattern. | G31: Tortured Phrase §13 | H31: P3
... A46: Design Contradiction | B46: Optional GPT-OSS Design Validation -- NON-GATING | C46: When enabled, GPT-OSS annotates a deterministic finding with confirmed/rejected/uncertain, but a `rejected` result does NOT remove or deactivate the finding -- it stays check_triggered=True. | D46: Low | E46: Enhance | F46: Highest-priority fix in this audit: gate the flag on validation_status exactly as Tortured Phrase and LLM Response Trace already do, so behavior -- and editor trust -- is consistent across all three LLM-validated checks. | G46: Numerical/Design/Trial §15, §29 | H46: P0
A47: Unverifiable Clinical Trial | B47: Registry-ID / Registration-Phrase Regex Extraction | C47: Deliberately permissive regexes extract NCT/ISRCTN/ACTRN/EUCTR/EudraCT/ChiCTR references plus placeholder ('pending', 'TBD') and no-ID registration claims. | D47: Medium | E47: Enhance | F47: Supported-registry list omits several registries in active global use (India's CTRI, Germany's DRKS, Japan's jRCT, Iran's IRCT). For an internationally-submitted corpus this is a real, if low-severity, coverage gap. | G47: Numerical/Design/Trial §19 | H47: P2 | I47: Groundwork only — Phase 1 (2026-08-19). The registry-prefix list was found hardcoded 4 separate times (not the vocabulary triplication the audit's OE-08 originally described elsewhere — that claim didn't hold). Consolidated to one SUPPORTED_REGISTRY_PREFIXES tuple in template_matching_common.py so a future registry addition is a one-line change. The actual coverage gap named in this row (CTRI, DRKS, jRCT, IRCT, WHO ICTRP still unsupported) is UNCHANGED — that expansion remains Phase 3 and this row's Verdict/Viability are intentionally left as-is.
A48: Unverifiable Clinical Trial | B48: Per-Registry Format Validators (full-match regex incl. digit-count rules) | C48: Full regex-match validation per registry (e.g. NCT + exactly 8 digits; ACTRN + 14 digits), with normalization of spaces/dashes/underscores for NCT IDs. | D48: High | E48: Keep | F48: No change needed. | G48: Numerical/Design/Trial §20 | H48: P3
A49: Unverifiable Clinical Trial | B49: Local Classification (placeholder / no-ID / malformed / unsupported registry) | C49: Claims that don't need a network call are classified deterministically without ever reaching the registry adapter. | D49: High | E49: Keep | F49: No change needed -- correct separation of concerns between local classification and authoritative lookup. | G49: Numerical/Design/Trial §21 | H49: P3
A50: Unverifiable Clinical Trial | B50: ClinicalTrials.gov API v2 Adapter (urllib, 10s timeout, 2 retries, exponential backoff, 429/5xx retryable) | C50: Hand-rolled urllib.request client with explicit timeout/retry/backoff and correct treatment of HTTP 404 as authoritative not_found rather than an error. | D50: High | E50: Keep | F50: Best-engineered external dependency in the codebase -- use as the template for bringing GPT-OSS call sites up to the same standard (see P2 LLM orchestration row). | G50: Numerical/Design/Trial §22 | H50: P3
A51: Unverifiable Clinical Trial | B51: Registry-Result Self-Consistency Validation | C51: Returned adapter objects are checked for registry-name match, ID match, found/verified consistency, and correct external-ID echoing before being trusted. | D51: High | E51: Keep | F51: Excellent defensive check against a malformed or mismatched adapter response; no change needed. | G51: Numerical/Design/Trial §23 | H51: P3
A52: Unverifiable Clinical Trial | B52: Verified/Not-Found Cache (atomic os.replace, offline_cache_only mode) | C52: Only `verified` and `not_found` are cached; writes are atomic; disabling live verification still allows previously-cached authoritative results to be used. | D52: High | E52: Keep | F52: No change needed -- well-designed cache semantics with a sensible offline fallback. | G52: Numerical/Design/Trial §24 | H52: P3
A53: Unverifiable Clinical Trial | B53: `urllib.request` as the HTTP Layer | C53: Standard-library urllib is used directly rather than a session-based HTTP client. | D53: Medium | E53: Enhance | F53: Current behavior is documented and correct; low-priority swap to `requests`/`httpx` with a pooled session would reduce hand-rolled edge-case surface (redirects, TLS, charset) on any future touch of this module. | G53: Numerical/Design/Trial §22 | H53: P3
A54: Consolidated Workbook / Reporting | B54: All Abstracts Sheet Generation | C54: Master list with a Templating (Cross-Author) Y/N column alongside every other integrity check, per abstract. | D54: High | E54: Keep | F54: No change needed. | G54: PRD v1 §9; Template Detection §13 | H54: P3
...

Sheet Overengineering Log
A1: Over-Engineering & Narrow-Solution Log — the sharpest, named issues in the documented architecture: silent failures, dead code, hardcoded edges, and heuristics that will not survive messy production data. Cross-referenced to the Refactoring Roadmap phase that resolves each one.
A2: Issue ID | B2: Pipeline(s) Affected | C2: Pattern Type | D2: Description | E2: Real-World Failure Scenario | F2: Severity | G2: Recommended Fix | H2: Roadmap Phase | I2: Resolution Status (Phase 0/1 verification)
A3: OE-01 | B3: XML Ingestion & Record Parsing; Numerical Contradiction; Design Contradiction; Unverifiable Clinical Trial | C3: Duplicated Logic | D3: The naive sentence splitter regex (?<=[.!?])\s+ is independently reimplemented in at least three detector modules instead of living in one shared utility. | E3: Common biomedical abbreviations (Fig., vs., e.g., no., i.v.) and decimal-adjacent punctuation fracture sentences, corrupting numeric-claim boundaries and the exact-context windows sent to GPT-OSS -- and any future fix has to be applied N times, not once. | F3: High | G3: Extract one shared sentence_split() utility using an abbreviation-aware tokenizer (pySBD or a spaCy rule-based sentencizer); delete every per-module copy. | H3: Phase 1 | I3: Partially resolved — Phase 1 (2026-08-19). Audit named 3 call sites; investigation found 8 independent implementations. Consolidated the true duplicates into content_integrity.utils.split_sentences() (template_matching_common._sentence_split, entity_substitutions.py, signal_validation.py, enriched_reporting.py) and fixed a latent index-misalignment bug this duplication caused between entity_extraction.py and entity_substitutions.py. NOT done: still the naive regex, not an abbreviation-aware tokenizer — Fig./vs./e.g./i.v. still fracture sentences. The span-based variants (template_features.py, detectors/llm_trace_context.py) and tortured_phrase.py's boundary regex were deliberately deferred to the Phase 3 abbreviation-aware pass this row's Recommended Fix describes.
A4: OE-02 | B4: Tortured Phrase Detection | C4: Silent Failure | D4: Dictionary rules can carry a proximity operator like "phrase"~5, but the parser strips the ~5 while loading the rule and never enforces the distance constraint. | E4: A rule author reasonably believes two terms must appear within 5 words of each other; in production the rule silently matches them anywhere in the whole title/abstract field, quietly widening the rule's blast radius with no error, warning, or log entry anywhere. | F4: High | G4: Either implement true windowed-proximity matching, or reject/warn loudly at dictionary-load time when ~N is present so rule authors know the operator is unsupported. | H4: Phase 2 | I4: Resolved — Phase 2 (2026-08-19). Added warning at tortured-phrase dictionary-load time (load_tortured_rules) when ~N proximity operator appears on single-token rules (unsupported; proximity matching requires 2+ tokens). Rule authors now see explicit stacklevel=2 warning instead of silent discard, closing the gap between perceived and actual rule behavior.
A5: OE-03 | B5: Design Contradiction | C5: Over-Engineered (dead compute) / Inconsistent Behavior | D5: GPT-OSS validates every design-contradiction candidate, but a rejected result never suppresses the finding -- it is stored as an annotation while check_triggered stays True. | E5: An editor can see an active 'contradiction found' flag sitting directly next to an internally-stored 'rejected' reason. The first time someone notices this, trust in every other check erodes -- and today the org pays LLM latency/cost for a signal that structurally cannot change the outcome. | F5: Critical | G5: Gate the flag on validation_status exactly as Tortured Phrase and LLM Response Trace already do (confirmed/rejected/uncertain controls the active result). | H5: Phase 2 | I5: Resolved — Phase 2 (2026-08-19). Design contradiction findings now gate check_triggered on validation_status exactly as tortured_phrase and llm_response_trace do: when GPT-OSS validation returns 'rejected', the finding is marked check_triggered=False, making it inactive so it no longer displays as flagged. Verified by new test: test_rejected_validation_deactivates_detected_contradiction.
A6: OE-04 | B6: Template Detection (Cross-Author) | C6: Narrow Solution That Breaks at Scale | D6: Candidate retrieval is justified in the design doc specifically for '~6,000 abstracts, one annual batch'; the PRD's own open questions ask whether historical, multi-year comparison is needed. | E6: Comparing against several cumulative years of abstracts turns an already-nontrivial pairwise/blocking pass into a real compute-time cliff -- or forces someone to quietly narrow the blocking window just to keep runtime acceptable, which raises false-negative risk without anyone deciding that on purpose. | F6: Medium | G6: Introduce an ANN/MinHash-LSH candidate-generation layer ahead of the existing deterministic classifiers; the classification logic itself does not need to change, preserving auditability. | H6: Phase 4
A7: OE-05 | B7: Template Detection (Cross-Author) | C7: Dead / Orphaned Capability | D7: Connected-component clustering of template families (≥3 linked abstracts) is fully implemented as a graph structure but explicitly documented as not surfaced to editors. | E7: Ongoing maintenance cost for a feature nobody consumes -- and editors reviewing 5 separate pairwise rows for what is actually one 5-abstract templated family never see the single strongest signal the system already computed: family size. | F7: Medium | G7: Ship a minimal Template Family view, or delete the code path. Do not leave a half-built capability as permanent technical debt. | H7: Phase 1 | I7: Deferred, not shipped or removed — Phase 1 (2026-08-19). Verified the family data already reaches content_integrity_results.json but not the workbook or frontend. By explicit product decision: kept the code, did not ship a view (value to editors unproven), did not delete it. Documented in family_clustering.py's module docstring. This does not satisfy the Recommended Fix's ship-or-delete framing — it's a deliberate third option (defer, with the reasoning made visible).
A8: OE-06 | B8: All pipelines | C8: Hardcoded Threshold / Maintainability Debt | D8: At least 15 distinct numeric thresholds (similarity cutoffs, word-count minimums, confidence mappings, timeouts, tolerances) are hardcoded independently inside separate detector modules. | E8: Tuning the system for a different conference or a noisier dataset (a realistic future need) means hunting through six codebases instead of editing one file; two engineers can each 'fix' the same conceptual threshold in different places and silently diverge. | F8: Medium | G8: Single versioned config surface, extending the versioning discipline already used for the tortured-phrase dictionary to every threshold in the system. | H8: Phase 1 | I8: Resolved — Phase 1 (2026-08-19). ~50 constants across 15 files relocated to one file, content_integrity/thresholds.py; verified by repo-wide grep that no scattered module-level numeric threshold constants remain outside it. Versioned via the git commit sha already in run metadata (Phase 0), not a separate content-hash scheme like the tortured-phrase dictionary's — a deliberate, approved substitution since these are code-tuned knobs, not an externally-edited catalogue.
A9: OE-07 | B9: Tortured Phrase Detection; LLM Response Trace; Design Contradiction | C9: Narrow-Brittle (Inconsistent Resilience) | D9: The ClinicalTrials.gov adapter has explicit timeout/retry/backoff/caching; the three GPT-OSS call sites used across these pipelines document no equivalent resilience pattern. | E9: A transient IntelliHub rate-limit or outage during a ~6,000-abstract run can silently degrade or fail an unknown number of tortured-phrase / LLM-trace / design-contradiction validations, with none of the retry/backoff discipline the registry lookups already have. | F9: High | G9: One shared LLM client wrapper with the same timeout/retry/backoff/cache discipline as the registry adapter, used uniformly by all three call sites. | H9: Phase 3
A10: OE-08 | B10: Template Detection (Cross-Author); Tortured Phrase Detection; Unverifiable Clinical Trial | C10: Narrow-Brittle (Static Vocabulary) | D10: Entity recognition and registry coverage depend on static, hand-maintained lists: gene names, drug-name suffixes, disease terms, and a fixed set of 6 supported trial registries. | E10: New drug classes, newly-approved gene nomenclature, or a trial registered in CTRI/DRKS/jRCT/IRCT all fall outside every relevant list at once, degrading masking quality, new-phrase discovery, and trial verification coverage together -- because they are three separately-maintained copies of 'the same idea.' | F10: Medium | G10: Source vocabulary from maintained external references (HGNC gene symbols, WHO INN drug stems, WHO ICTRP registry list) on a refresh cadence; consolidate into one shared biomedical-vocabulary module reused by all three pipelines instead of three private copies. | H10: Phase 3 | I10: Partially resolved — Phase 1 (2026-08-19). The 'three separately-maintained vocabulary copies' claim did not hold on inspection: template_matching_common.py already exists as one shared module for gene/drug/trial-ID patterns, reused by entity_extraction.py, entity_normalized_template.py, and unverifiable_trial.py; tortured_phrase.py has no vocabulary at all (it loads an unrelated CSV phrase dictionary). The genuine duplication found — the trial-registry prefix list hand-typed 4 times in/around unverifiable_trial.py — is now built from one SUPPORTED_REGISTRY_PREFIXES tuple, with an assertion keeping REGISTRY_NAMES in sync. Registry coverage itself (CTRI/DRKS/jRCT/IRCT/WHO ICTRP) is unchanged and remains Phase 3.
A11: OE-09 | B11: Numerical Contradiction | C11: Narrow Solution (Documented V1 Gap) | D11: The detector cannot connect a population count stated in one sentence to a percentage or count stated in a later sentence -- explicitly acknowledged as sentence-local-only in the design doc. | E11: The single most common numeric-contradiction pattern in real abstracts ('120 patients were enrolled. ... the response rate was 45% (58/110).') is structurally invisible today, because N and the percentage claim live in different sentences. | F11: High | G11: Add a lightweight cross-sentence 'most recently stated N' carry-forward pass ahead of the existing arithmetic rules -- no LLM or embeddings required. | H11: Phase 3
A12: OE-10 | B12: Orchestration & Risk Aggregation; Editor Frontend & Evals | C12: Over-Simplification (value destroyed downstream) | D12: Every detector computes a graded High/Medium/Low/None priority using deliberate evidence-combination rules, but the frontend collapses all of it to 'any flag = High, else Low.' | E12: A Low-priority 'unsupported registry, manual verification' finding is presented to editors with exactly the same visual urgency as a 'trial not found' or an exact-duplicate-abstract finding -- directly undermining the PRD's own stated goal of helping editors prioritize investigation. | F12: High | G12: Surface the native per-check priority each detector already computes instead of re-deriving a cruder binary signal at the presentation layer. | H12: Phase 2

Sheet Refactoring Roadmap
A1: Refactoring Roadmap & Phased Execution — ordered by trust/correctness risk first, then real-world robustness, then scale. Each milestone cross-references the Overengineering Log issue(s) it resolves (see OE-xx codes).
A2: Phase | B2: Milestone | C2: Target Duration | D2: Scope / Key Changes | E2: Rationale | F2: Effort | G2: Dependencies | H2: Success Criteria | I2: Status
A3: Phase 0 | B3: Stabilize & Instrument | C3: 1–2 wks | D3: Add run metadata + dictionary/rule-version stamping visible in the workbook for every rule source (not just tortured phrases); add structured parse-failure and record-exclusion reporting; add latency/success telemetry around every GPT-OSS call site. | E3: You cannot safely refactor a system you can't yet observe. This phase adds guardrails and visibility without changing any detector's behavior, so it de-risks everything that follows. | F3: S | G3: None | H3: Every pipeline run produces one run report showing parse failures, rule/dictionary versions, and LLM call success/latency stats. | I3: Done — 2026-08-19. Verified against this phase's own Success Criteria: a smoke pipeline run's 'How This Works' sheet shows failed_files/parsed_with_warnings counts, per-record operational issues for every parse failure and check exclusion, version stamps for every rule source (tortured dictionary, LLM-trace catalogue, template features, pair classifier, signal validation, family clustering, editorial scoring, entity vocabulary, design-contradiction rule table and prompt), and llm_gateway_request/success/failure/retry_count plus total/avg/max latency for the shared GPT-OSS client. Full test suite green (262 passed) apart from one pre-existing, unrelated failure.
A4: Phase 1 | B4: De-Bloat & Consolidate | C4: 3–4 wks | D4: Extract one shared sentence-tokenizer utility and delete 3+ duplicated regex splitters (OE-01); extract one shared biomedical-vocabulary module for genes/drugs/registries reused by Template Detection, Tortured Phrase, and Clinical Trial (OE-08, partial); centralize all thresholds/magic numbers into one versioned config (OE-06); decide and execute ship-or-delete on Template-Family graph clustering (OE-05). | E4: Remove duplication and dead weight before adding new capability, so every subsequent change touches one place instead of several silent copies. | F4: M | G4: Phase 0 telemetry confirms nothing relies on the old duplicated behavior | H4: A repo-wide search shows a single sentence-splitter implementation; changing a threshold requires editing exactly one config file; Template Family is either a real feature or gone. | I4: Partially done — 2026-08-19. 2 of 3 stated Success Criteria fully met: (1) NOT fully met — a repo-wide search shows one canonical sentence-splitter (content_integrity.utils.split_sentences) plus 3 deliberately out-of-scope span/boundary variants, not literally one implementation; abbreviation-awareness is still Phase 3. (2) Met — content_integrity/thresholds.py is the single file for every threshold. (3) NOT met as originally framed — Template Family was deliberately deferred (kept, undocumented no longer, but not shipped or removed) rather than resolved ship-or-delete, per explicit product decision. OE-08's registry-prefix duplication was also found and fixed as part of this phase (registry coverage expansion itself remains Phase 3). Full test suite green apart from the same pre-existing unrelated failure.
A5: Phase 2 | B5: Fix Trust-Breaking Inconsistencies | C5: 1–2 wks | D5: Gate the Design Contradiction flag on its own LLM validation_status, matching Tortured Phrase / LLM Response Trace behavior (OE-03); fix or explicitly disable the silently-ignored ~5 proximity operator in the tortured-phrase dictionary (OE-02); replace the binary High/Low risk collapse with the graded priority every detector already computes (OE-10). | E5: These are the clearest cases where the system's actual behavior silently diverges from what an editor would reasonably assume it does. High trust impact, low engineering cost -- fix before anything more ambitious. | F5: S | G5: Phase 0 telemetry confirms no hidden dependents on current non-gating/binary behavior | H5: All three LLM-validated checks behave identically (confirmed/rejected/uncertain drives the same gating logic); a dictionary rule using ~N either enforces it or fails to load with a clear error; the editor-facing risk badge reflects native per-check severity. | I5: Done — 2026-08-19. OE-03 (CRITICAL) resolved: design_contradiction findings now gate check_triggered on validation_status, deactivating rejected findings. OE-02 resolved: tortured-phrase dictionary-load warns loudly on unsupported ~N single-token proximity. OE-10 verification: graded priority (None/Low/Medium/High) already exists in _risk_from_signals; exported as overall_content_risk in summary. Full test suite green (261 passed) plus 2 new subtest variants on OE-03.
A6: Phase 3 | B6: Harden Real-World Robustness | C6: 4–6 wks | D6: Replace the shared sentence splitter with a proper abbreviation-aware tokenizer (completes OE-01); add cross-sentence numeric linking to Numerical Contradiction (OE-09); expand supported clinical-trial registries (CTRI, DRKS, jRCT, IRCT, WHO ICTRP) (OE-08); bring all GPT-OSS call sites up to the same resilience standard as the ClinicalTrials.gov adapter (OE-07). | E6: These are the concrete, evidenced brittleness points most likely to misfire on real, messy submission data at production volume -- the core ask of this audit. | F6: L | G6: Phase 1 shared utilities and config surface exist | H6: Documented before/after recall on a labeled sample for numerical contradictions; measured GPT-OSS call success rate under induced-failure testing; registry coverage matches ASCO's actual international submitter base.
A7: Phase 4 | B7: Scale the Architecture | C7: Ongoing, as volume grows | D7: Introduce ANN/MinHash-LSH candidate generation ahead of Template Detection's deterministic classifiers to remove the pairwise O(n²) ceiling (OE-04); surface currently-computed-but-hidden structured fields (numerical calculated_value/difference, trial registry metadata, design validation reason) in the workbook/UI; calibrate the fixed low/med/high confidence mapping in tortured-phrase discovery against real editor accept/reject history. | E7: Unlocks value the system already computes internally and removes the one clear scalability ceiling, without touching the deterministic-first philosophy that gives the system its explainability and editorial trust. | F7: L | G7: Phases 0–2 complete; sufficient review-history data for calibration | H7: Template-detection runtime stays sub-quadratic-feeling as the corpus grows across years; editors report priority badges match their own sense of urgency; zero 'computed but hidden' fields remain undocumented.
